<?xml version="1.0" ?>
<!-- =================================================================================== -->
<!-- |    This document was autogenerated by xacro from mistletoe-v4.xacro             | -->
<!-- |    EDITING THIS FILE BY HAND IS NOT RECOMMENDED                                 | -->
<!-- =================================================================================== -->
<robot name="mistletoe-v4">
  <material name="silver_default">
    <color rgba="0.700 0.700 0.700 1.000"/>
  </material>
  <material name="steel_satin">
    <color rgba="0.6274509803921569 0.6274509803921569 0.6274509803921569 1.0"/>
  </material>
  <transmission name="HFE_1_tran">
    <type>transmission_interface/SimpleTransmission</type>
    <joint name="HFE_1">
      <hardwareInterface>hardware_interface/EffortJointInterface</hardwareInterface>
    </joint>
    <actuator name="HFE_1_actr">
      <hardwareInterface>hardware_interface/EffortJointInterface</hardwareInterface>
      <mechanicalReduction>1</mechanicalReduction>
    </actuator>
  </transmission>
  <transmission name="HFE_2_tran">
    <type>transmission_interface/SimpleTransmission</type>
    <joint name="HFE_2">
      <hardwareInterface>hardware_interface/EffortJointInterface</hardwareInterface>
    </joint>
    <actuator name="HFE_2_actr">
      <hardwareInterface>hardware_interface/EffortJointInterface</hardwareInterface>
      <mechanicalReduction>1</mechanicalReduction>
    </actuator>
  </transmission>
  <transmission name="HFE_3_tran">
    <type>transmission_interface/SimpleTransmission</type>
    <joint name="HFE_3">
      <hardwareInterface>hardware_interface/EffortJointInterface</hardwareInterface>
    </joint>
    <actuator name="HFE_3_actr">
      <hardwareInterface>hardware_interface/EffortJointInterface</hardwareInterface>
      <mechanicalReduction>1</mechanicalReduction>
    </actuator>
  </transmission>
  <transmission name="HFE_4_tran">
    <type>transmission_interface/SimpleTransmission</type>
    <joint name="HFE_4">
      <hardwareInterface>hardware_interface/EffortJointInterface</hardwareInterface>
    </joint>
    <actuator name="HFE_4_actr">
      <hardwareInterface>hardware_interface/EffortJointInterface</hardwareInterface>
      <mechanicalReduction>1</mechanicalReduction>
    </actuator>
  </transmission>
  <transmission name="KFE_1_tran">
    <type>transmission_interface/SimpleTransmission</type>
    <joint name="KFE_1">
      <hardwareInterface>hardware_interface/EffortJointInterface</hardwareInterface>
    </joint>
    <actuator name="KFE_1_actr">
      <hardwareInterface>hardware_interface/EffortJointInterface</hardwareInterface>
      <mechanicalReduction>1</mechanicalReduction>
    </actuator>
  </transmission>
  <transmission name="KFE_2_tran">
    <type>transmission_interface/SimpleTransmission</type>
    <joint name="KFE_2">
      <hardwareInterface>hardware_interface/EffortJointInterface</hardwareInterface>
    </joint>
    <actuator name="KFE_2_actr">
      <hardwareInterface>hardware_interface/EffortJointInterface</hardwareInterface>
      <mechanicalReduction>1</mechanicalReduction>
    </actuator>
  </transmission>
  <transmission name="KFE_3_tran">
    <type>transmission_interface/SimpleTransmission</type>
    <joint name="KFE_3">
      <hardwareInterface>hardware_interface/EffortJointInterface</hardwareInterface>
    </joint>
    <actuator name="KFE_3_actr">
      <hardwareInterface>hardware_interface/EffortJointInterface</hardwareInterface>
      <mechanicalReduction>1</mechanicalReduction>
    </actuator>
  </transmission>
  <transmission name="KFE_4_tran">
    <type>transmission_interface/SimpleTransmission</type>
    <joint name="KFE_4">
      <hardwareInterface>hardware_interface/EffortJointInterface</hardwareInterface>
    </joint>
    <actuator name="KFE_4_actr">
      <hardwareInterface>hardware_interface/EffortJointInterface</hardwareInterface>
      <mechanicalReduction>1</mechanicalReduction>
    </actuator>
  </transmission>
  <transmission name="HAA_1_tran">
    <type>transmission_interface/SimpleTransmission</type>
    <joint name="HAA_1">
      <hardwareInterface>hardware_interface/EffortJointInterface</hardwareInterface>
    </joint>
    <actuator name="HAA_1_actr">
      <hardwareInterface>hardware_interface/EffortJointInterface</hardwareInterface>
      <mechanicalReduction>1</mechanicalReduction>
    </actuator>
  </transmission>
  <transmission name="HAA_2_tran">
    <type>transmission_interface/SimpleTransmission</type>
    <joint name="HAA_2">
      <hardwareInterface>hardware_interface/EffortJointInterface</hardwareInterface>
    </joint>
    <actuator name="HAA_2_actr">
      <hardwareInterface>hardware_interface/EffortJointInterface</hardwareInterface>
      <mechanicalReduction>1</mechanicalReduction>
    </actuator>
  </transmission>
  <transmission name="HAA_3_tran">
    <type>transmission_interface/SimpleTransmission</type>
    <joint name="HAA_3">
      <hardwareInterface>hardware_interface/EffortJointInterface</hardwareInterface>
    </joint>
    <actuator name="HAA_3_actr">
      <hardwareInterface>hardware_interface/EffortJointInterface</hardwareInterface>
      <mechanicalReduction>1</mechanicalReduction>
    </actuator>
  </transmission>
  <transmission name="HAA_4_tran">
    <type>transmission_interface/SimpleTransmission</type>
    <joint name="HAA_4">
      <hardwareInterface>hardware_interface/EffortJointInterface</hardwareInterface>
    </joint>
    <actuator name="HAA_4_actr">
      <hardwareInterface>hardware_interface/EffortJointInterface</hardwareInterface>
      <mechanicalReduction>1</mechanicalReduction>
    </actuator>
  </transmission>
  <link name="base_link">
    <inertial>
      <origin rpy="0 0 0" xyz="8.934564205453908e-07 7.883956382581658e-07 -0.04550328898512308"/>
      <mass value="5.5104049208044765"/>
      <inertia ixx="0.020175" ixy="-0.0" ixz="-0.0" iyy="0.044213" iyz="-0.0" izz="0.057638"/>
    </inertial>
    <visual>
      <origin rpy="0 0 0" xyz="0 0 0"/>
      <geometry>
        <mesh filename="package://mistletoe-v4_description/meshes/base_link.stl" scale="0.001 0.001 0.001"/>
      </geometry>
      <material name="steel_satin"/>
    </visual>
    <collision>
      <origin rpy="0 0 0" xyz="0 0 0"/>
      <geometry>
        <mesh filename="package://mistletoe-v4_description/meshes/base_link.stl" scale="0.001 0.001 0.001"/>
      </geometry>
    </collision>
  </link>
  <link name="THIGH_1">
    <inertial>
      <origin rpy="0 0 0" xyz="0.0010935636942111804 0.051036250405863404 -0.04784660292125947"/>
      <mass value="0.7240002196192582"/>
      <inertia ixx="0.004023" ixy="1.7e-05" ixz="-4e-05" iyy="0.003876" iyz="0.000584" izz="0.000791"/>
    </inertial>
    <visual>
      <origin rpy="0 0 0" xyz="-0.19975 -0.08775 0.0455"/>
      <geometry>
        <mesh filename="package://mistletoe-v4_description/meshes/THIGH_1.stl" scale="0.001 0.001 0.001"/>
      </geometry>
      <material name="steel_satin"/>
    </visual>
    <collision>
      <origin rpy="0 0 0" xyz="-0.19975 -0.08775 0.0455"/>
      <geometry>
        <mesh filename="package://mistletoe-v4_description/meshes/THIGH_1.stl" scale="0.001 0.001 0.001"/>
      </geometry>
    </collision>
  </link>
  <link name="THIGH_2">
    <inertial>
      <origin rpy="0 0 0" xyz="-0.001093563694208266 -0.05103625040585741 -0.04784660292126859"/>
      <mass value="0.7240002196192582"/>
      <inertia ixx="0.004023" ixy="1.7e-05" ixz="4e-05" iyy="0.003876" iyz="-0.000584" izz="0.000791"/>
    </inertial>
    <visual>
      <origin rpy="0 0 0" xyz="-0.19975 0.08775 0.0455"/>
      <geometry>
        <mesh filename="package://mistletoe-v4_description/meshes/THIGH_2.stl" scale="0.001 0.001 0.001"/>
      </geometry>
      <material name="steel_satin"/>
    </visual>
    <collision>
      <origin rpy="0 0 0" xyz="-0.19975 0.08775 0.0455"/>
      <geometry>
        <mesh filename="package://mistletoe-v4_description/meshes/THIGH_2.stl" scale="0.001 0.001 0.001"/>
      </geometry>
    </collision>
  </link>
  <link name="THIGH_3">
    <inertial>
      <origin rpy="0 0 0" xyz="0.0010935636941983018 0.05103625040585985 -0.04784660292125947"/>
      <mass value="0.7240002196192582"/>
      <inertia ixx="0.004023" ixy="1.7e-05" ixz="-4e-05" iyy="0.003876" iyz="0.000584" izz="0.000791"/>
    </inertial>
    <visual>
      <origin rpy="0 0 0" xyz="0.19975 -0.08775 0.0455"/>
      <geometry>
        <mesh filename="package://mistletoe-v4_description/meshes/THIGH_3.stl" scale="0.001 0.001 0.001"/>
      </geometry>
      <material name="steel_satin"/>
    </visual>
    <collision>
      <origin rpy="0 0 0" xyz="0.19975 -0.08775 0.0455"/>
      <geometry>
        <mesh filename="package://mistletoe-v4_description/meshes/THIGH_3.stl" scale="0.001 0.001 0.001"/>
      </geometry>
    </collision>
  </link>
  <link name="THIGH_4">
    <inertial>
      <origin rpy="0 0 0" xyz="-0.0010935636942024096 -0.05103625040586318 -0.047846602921261486"/>
      <mass value="0.7240002196192582"/>
      <inertia ixx="0.004023" ixy="1.7e-05" ixz="4e-05" iyy="0.003876" iyz="-0.000584" izz="0.000791"/>
    </inertial>
    <visual>
      <origin rpy="0 0 0" xyz="0.19975 0.08775 0.0455"/>
      <geometry>
        <mesh filename="package://mistletoe-v4_description/meshes/THIGH_4.stl" scale="0.001 0.001 0.001"/>
      </geometry>
      <material name="steel_satin"/>
    </visual>
    <collision>
      <origin rpy="0 0 0" xyz="0.19975 0.08775 0.0455"/>
      <geometry>
        <mesh filename="package://mistletoe-v4_description/meshes/THIGH_4.stl" scale="0.001 0.001 0.001"/>
      </geometry>
    </collision>
  </link>
  <link name="SHANK_1">
    <inertial>
      <origin rpy="0 0 0" xyz="8.778158588906848e-09 -0.04792404704971809 -0.05711326657615318"/>
      <mass value="0.08133302860327428"/>
      <inertia ixx="0.000324" ixy="0.0" ixz="0.0" iyy="0.000305" iyz="-4.7e-05" izz="3.6e-05"/>
    </inertial>
    <visual>
      <origin rpy="0 0 0" xyz="-0.19975 -0.17891 0.2254"/>
      <geometry>
        <mesh filename="package://mistletoe-v4_description/meshes/SHANK_1.stl" scale="0.001 0.001 0.001"/>
      </geometry>
      <material name="steel_satin"/>
    </visual>
    <collision>
      <origin rpy="0 0 0" xyz="-0.19975 -0.17891 0.2254"/>
      <geometry>
        <mesh filename="package://mistletoe-v4_description/meshes/SHANK_1.stl" scale="0.001 0.001 0.001"/>
      </geometry>
    </collision>
  </link>
  <link name="SHANK_2">
    <inertial>
      <origin rpy="0 0 0" xyz="-8.778152343902335e-09 0.04792404704972353 -0.05711326657615601"/>
      <mass value="0.08133302860327428"/>
      <inertia ixx="0.000324" ixy="0.0" ixz="-0.0" iyy="0.000305" iyz="4.7e-05" izz="3.6e-05"/>
    </inertial>
    <visual>
      <origin rpy="0 0 0" xyz="-0.19975 0.17891 0.2254"/>
      <geometry>
        <mesh filename="package://mistletoe-v4_description/meshes/SHANK_2.stl" scale="0.001 0.001 0.001"/>
      </geometry>
      <material name="steel_satin"/>
    </visual>
    <collision>
      <origin rpy="0 0 0" xyz="-0.19975 0.17891 0.2254"/>
      <geometry>
        <mesh filename="package://mistletoe-v4_description/meshes/SHANK_2.stl" scale="0.001 0.001 0.001"/>
      </geometry>
    </collision>
  </link>
  <link name="SHANK_3">
    <inertial>
      <origin rpy="0 0 0" xyz="8.778171217693753e-09 -0.04792404704972264 -0.057113266576134136"/>
      <mass value="0.08133302860327428"/>
      <inertia ixx="0.000324" ixy="0.0" ixz="0.0" iyy="0.000305" iyz="-4.7e-05" izz="3.6e-05"/>
    </inertial>
    <visual>
      <origin rpy="0 0 0" xyz="0.19975 -0.17891 0.2254"/>
      <geometry>
        <mesh filename="package://mistletoe-v4_description/meshes/SHANK_3.stl" scale="0.001 0.001 0.001"/>
      </geometry>
      <material name="steel_satin"/>
    </visual>
    <collision>
      <origin rpy="0 0 0" xyz="0.19975 -0.17891 0.2254"/>
      <geometry>
        <mesh filename="package://mistletoe-v4_description/meshes/SHANK_3.stl" scale="0.001 0.001 0.001"/>
      </geometry>
    </collision>
  </link>
  <link name="SHANK_4">
    <inertial>
      <origin rpy="0 0 0" xyz="-8.778185067725985e-09 0.04792404704972175 -0.05711326657613752"/>
      <mass value="0.08133302860327428"/>
      <inertia ixx="0.000324" ixy="0.0" ixz="-0.0" iyy="0.000305" iyz="4.7e-05" izz="3.6e-05"/>
    </inertial>
    <visual>
      <origin rpy="0 0 0" xyz="0.19975 0.17891 0.2254"/>
      <geometry>
        <mesh filename="package://mistletoe-v4_description/meshes/SHANK_4.stl" scale="0.001 0.001 0.001"/>
      </geometry>
      <material name="steel_satin"/>
    </visual>
    <collision>
      <origin rpy="0 0 0" xyz="0.19975 0.17891 0.2254"/>
      <geometry>
        <mesh filename="package://mistletoe-v4_description/meshes/SHANK_4.stl" scale="0.001 0.001 0.001"/>
      </geometry>
    </collision>
  </link>
  <link name="HIP_1">
    <inertial>
      <origin rpy="0 0 0" xyz="0.04348674344436504 0.0003320078953301872 -3.069574053486679e-06"/>
      <mass value="0.5061938145713982"/>
      <inertia ixx="0.000367" ixy="-0.0" ixz="-2e-06" iyy="0.000507" iyz="-1e-06" izz="0.00044"/>
    </inertial>
    <visual>
      <origin rpy="0 0 0" xyz="-0.153 -0.057 0.0455"/>
      <geometry>
        <mesh filename="package://mistletoe-v4_description/meshes/HIP_1.stl" scale="0.001 0.001 0.001"/>
      </geometry>
      <material name="steel_satin"/>
    </visual>
    <collision>
      <origin rpy="0 0 0" xyz="-0.153 -0.057 0.0455"/>
      <geometry>
        <mesh filename="package://mistletoe-v4_description/meshes/HIP_1.stl" scale="0.001 0.001 0.001"/>
      </geometry>
    </collision>
  </link>
  <link name="HIP_2">
    <inertial>
      <origin rpy="0 0 0" xyz="0.04348674344436615 -0.0003320078953261904 3.069574053611579e-06"/>
      <mass value="0.5061938145713982"/>
      <inertia ixx="0.000367" ixy="0.0" ixz="2e-06" iyy="0.000507" iyz="-1e-06" izz="0.00044"/>
    </inertial>
    <visual>
      <origin rpy="0 0 0" xyz="-0.153 0.057 0.0455"/>
      <geometry>
        <mesh filename="package://mistletoe-v4_description/meshes/HIP_2.stl" scale="0.001 0.001 0.001"/>
      </geometry>
      <material name="steel_satin"/>
    </visual>
    <collision>
      <origin rpy="0 0 0" xyz="-0.153 0.057 0.0455"/>
      <geometry>
        <mesh filename="package://mistletoe-v4_description/meshes/HIP_2.stl" scale="0.001 0.001 0.001"/>
      </geometry>
    </collision>
  </link>
  <link name="HIP_3">
    <inertial>
      <origin rpy="0 0 0" xyz="-0.04348674344436626 0.00033200789532639163 3.0695740536393346e-06"/>
      <mass value="0.5061938145713982"/>
      <inertia ixx="0.000367" ixy="0.0" ixz="-2e-06" iyy="0.000507" iyz="1e-06" izz="0.00044"/>
    </inertial>
    <visual>
      <origin rpy="0 0 0" xyz="0.153 -0.057 0.0455"/>
      <geometry>
        <mesh filename="package://mistletoe-v4_description/meshes/HIP_3.stl" scale="0.001 0.001 0.001"/>
      </geometry>
      <material name="steel_satin"/>
    </visual>
    <collision>
      <origin rpy="0 0 0" xyz="0.153 -0.057 0.0455"/>
      <geometry>
        <mesh filename="package://mistletoe-v4_description/meshes/HIP_3.stl" scale="0.001 0.001 0.001"/>
      </geometry>
    </collision>
  </link>
  <link name="HIP_4">
    <inertial>
      <origin rpy="0 0 0" xyz="-0.04348674344436532 -0.00033200789533001374 -3.0695740535699456e-06"/>
      <mass value="0.5061938145713982"/>
      <inertia ixx="0.000367" ixy="-0.0" ixz="2e-06" iyy="0.000507" iyz="1e-06" izz="0.00044"/>
    </inertial>
    <visual>
      <origin rpy="0 0 0" xyz="0.153 0.057 0.0455"/>
      <geometry>
        <mesh filename="package://mistletoe-v4_description/meshes/HIP_4.stl" scale="0.001 0.001 0.001"/>
      </geometry>
      <material name="steel_satin"/>
    </visual>
    <collision>
      <origin rpy="0 0 0" xyz="0.153 0.057 0.0455"/>
      <geometry>
        <mesh filename="package://mistletoe-v4_description/meshes/HIP_4.stl" scale="0.001 0.001 0.001"/>
      </geometry>
    </collision>
  </link>
  <link name="FOOT_1">
    <inertial>
      <origin rpy="0 0 0" xyz="-1.0547118733938987e-15 3.982925100842749e-15 -3.7518991807816704e-07"/>
      <mass value="0.11097676048805943"/>
      <inertia ixx="1e-05" ixy="0.0" ixz="0.0" iyy="1e-05" iyz="-0.0" izz="1e-05"/>
    </inertial>
    <visual>
      <origin rpy="0 0 0" xyz="-0.19975 -0.12091 0.397904"/>
      <geometry>
        <mesh filename="package://mistletoe-v4_description/meshes/FOOT_1.stl" scale="0.001 0.001 0.001"/>
      </geometry>
      <material name="steel_satin"/>
    </visual>
    <collision>
      <origin rpy="0 0 0" xyz="-0.19975 -0.12091 0.397904"/>
      <geometry>
        <mesh filename="package://mistletoe-v4_description/meshes/FOOT_1.stl" scale="0.001 0.001 0.001"/>
      </geometry>
    </collision>
  </link>
  <link name="FOOT_2">
    <inertial>
      <origin rpy="0 0 0" xyz="7.244205235679146e-15 -2.886579864025407e-15 -3.7518991713447747e-07"/>
      <mass value="0.11097676048805943"/>
      <inertia ixx="1e-05" ixy="0.0" ixz="0.0" iyy="1e-05" iyz="0.0" izz="1e-05"/>
    </inertial>
    <visual>
      <origin rpy="0 0 0" xyz="-0.19975 0.12091 0.397904"/>
      <geometry>
        <mesh filename="package://mistletoe-v4_description/meshes/FOOT_2.stl" scale="0.001 0.001 0.001"/>
      </geometry>
      <material name="steel_satin"/>
    </visual>
    <collision>
      <origin rpy="0 0 0" xyz="-0.19975 0.12091 0.397904"/>
      <geometry>
        <mesh filename="package://mistletoe-v4_description/meshes/FOOT_2.stl" scale="0.001 0.001 0.001"/>
      </geometry>
    </collision>
  </link>
  <link name="FOOT_3">
    <inertial>
      <origin rpy="0 0 0" xyz="1.9290125052862095e-14 -2.248201624865942e-15 -3.7518988832419e-07"/>
      <mass value="0.11097676048805943"/>
      <inertia ixx="1e-05" ixy="-0.0" ixz="-0.0" iyy="1e-05" iyz="-0.0" izz="1e-05"/>
    </inertial>
    <visual>
      <origin rpy="0 0 0" xyz="0.19975 -0.12091 0.397904"/>
      <geometry>
        <mesh filename="package://mistletoe-v4_description/meshes/FOOT_3.stl" scale="0.001 0.001 0.001"/>
      </geometry>
      <material name="steel_satin"/>
    </visual>
    <collision>
      <origin rpy="0 0 0" xyz="0.19975 -0.12091 0.397904"/>
      <geometry>
        <mesh filename="package://mistletoe-v4_description/meshes/FOOT_3.stl" scale="0.001 0.001 0.001"/>
      </geometry>
    </collision>
  </link>
  <link name="FOOT_4">
    <inertial>
      <origin rpy="0 0 0" xyz="-3.497202527569243e-14 2.55351295663786e-15 -3.7518989165485905e-07"/>
      <mass value="0.11097676048805943"/>
      <inertia ixx="1e-05" ixy="0.0" ixz="0.0" iyy="1e-05" iyz="-0.0" izz="1e-05"/>
    </inertial>
    <visual>
      <origin rpy="0 0 0" xyz="0.19975 0.12091 0.397904"/>
      <geometry>
        <mesh filename="package://mistletoe-v4_description/meshes/FOOT_4.stl" scale="0.001 0.001 0.001"/>
      </geometry>
      <material name="steel_satin"/>
    </visual>
    <collision>
      <origin rpy="0 0 0" xyz="0.19975 0.12091 0.397904"/>
      <geometry>
        <mesh filename="package://mistletoe-v4_description/meshes/FOOT_4.stl" scale="0.001 0.001 0.001"/>
      </geometry>
    </collision>
  </link>
  <joint name="HFE_1" type="continuous">
    <origin rpy="0 0 0" xyz="0.04675 0.03075 0.0"/>
    <parent link="HIP_1"/>
    <child link="THIGH_1"/>
    <axis xyz="-0.0 1.0 -0.0"/>
  </joint>
  <joint name="HFE_2" type="continuous">
    <origin rpy="0 0 0" xyz="0.04675 -0.03075 0.0"/>
    <parent link="HIP_2"/>
    <child link="THIGH_2"/>
    <axis xyz="0.0 -1.0 0.0"/>
  </joint>
  <joint name="HFE_3" type="continuous">
    <origin rpy="0 0 0" xyz="-0.04675 0.03075 0.0"/>
    <parent link="HIP_3"/>
    <child link="THIGH_3"/>
    <axis xyz="-0.0 1.0 0.0"/>
  </joint>
  <joint name="HFE_4" type="continuous">
    <origin rpy="0 0 0" xyz="-0.04675 -0.03075 0.0"/>
    <parent link="HIP_4"/>
    <child link="THIGH_4"/>
    <axis xyz="0.0 -1.0 0.0"/>
  </joint>
  <joint name="KFE_1" type="continuous">
    <origin rpy="0 0 0" xyz="0.0 0.09116 -0.1799"/>
    <parent link="THIGH_1"/>
    <child link="SHANK_1"/>
    <axis xyz="0.0 -1.0 -0.0"/>
  </joint>
  <joint name="KFE_2" type="continuous">
    <origin rpy="0 0 0" xyz="0.0 -0.09116 -0.1799"/>
    <parent link="THIGH_2"/>
    <child link="SHANK_2"/>
    <axis xyz="-0.0 1.0 0.0"/>
  </joint>
  <joint name="KFE_3" type="continuous">
    <origin rpy="0 0 0" xyz="0.0 0.09116 -0.1799"/>
    <parent link="THIGH_3"/>
    <child link="SHANK_3"/>
    <axis xyz="0.0 -1.0 -0.0"/>
  </joint>
  <joint name="KFE_4" type="continuous">
    <origin rpy="0 0 0" xyz="0.0 -0.09116 -0.1799"/>
    <parent link="THIGH_4"/>
    <child link="SHANK_4"/>
    <axis xyz="-0.0 1.0 0.0"/>
  </joint>
  <joint name="HAA_1" type="continuous">
    <origin rpy="0 0 0" xyz="0.153 0.057 -0.0455"/>
    <parent link="base_link"/>
    <child link="HIP_1"/>
    <axis xyz="1.0 0.0 -0.0"/>
  </joint>
  <joint name="HAA_2" type="continuous">
    <origin rpy="0 0 0" xyz="0.153 -0.057 -0.0455"/>
    <parent link="base_link"/>
    <child link="HIP_2"/>
    <axis xyz="1.0 0.0 -0.0"/>
  </joint>
  <joint name="HAA_3" type="continuous">
    <origin rpy="0 0 0" xyz="-0.153 0.057 -0.0455"/>
    <parent link="base_link"/>
    <child link="HIP_3"/>
    <axis xyz="-1.0 -0.0 0.0"/>
  </joint>
  <joint name="HAA_4" type="continuous">
    <origin rpy="0 0 0" xyz="-0.153 -0.057 -0.0455"/>
    <parent link="base_link"/>
    <child link="HIP_4"/>
    <axis xyz="-1.0 -0.0 0.0"/>
  </joint>
  <joint name="Rigid 34" type="fixed">
    <origin rpy="0 0 0" xyz="0.0 -0.058 -0.172504"/>
    <parent link="SHANK_1"/>
    <child link="FOOT_1"/>
  </joint>
  <joint name="Rigid 35" type="fixed">
    <origin rpy="0 0 0" xyz="0.0 0.058 -0.172504"/>
    <parent link="SHANK_2"/>
    <child link="FOOT_2"/>
  </joint>
  <joint name="Rigid 36" type="fixed">
    <origin rpy="0 0 0" xyz="0.0 -0.058 -0.172504"/>
    <parent link="SHANK_3"/>
    <child link="FOOT_3"/>
  </joint>
  <joint name="Rigid 37" type="fixed">
    <origin rpy="0 0 0" xyz="0.0 0.058 -0.172504"/>
    <parent link="SHANK_4"/>
    <child link="FOOT_4"/>
  </joint>
</robot>
